{"content": {"suites": {"0": {"status": {"total_pass": 0, "total_skip": 0, "total_xpass": 0, "total_xfail": 0, "total_rerun": 0, "total_fail": 1, "total_error": 0}, "tests": {"0": {"status": "FAIL", "message": "   socket.gaierror: [Errno 11001] getaddrinfo failed\n       urllib3.exceptions.NameResolutionError: <urllib3.connection.HTTPSConnection object at 0x0000028116169940>: Failed to resolve 'api-qa.example.com' ([Errno 11001] getaddrinfo failed)\n       urllib3.exceptions.MaxRetryError: HTTPSConnectionPool(host='api-qa.example.com', port=443): Max retries exceeded with url: /endpoint (Caused by NameResolutionError(\"<urllib3.connection.HTTPSConnection object at 0x0000028116169940>: Failed to resolve 'api-qa.example.com' ([Errno 11001] getaddrinfo failed)\"))\n       requests.exceptions.ConnectionError: HTTPSConnectionPool(host='api-qa.example.com', port=443): Max retries exceeded with url: /endpoint (Caused by NameResolutionError(\"<urllib3.connection.HTTPSConnection object at 0x0000028116169940>: Failed to resolve 'api-qa.example.com' ([Errno 11001] getaddrinfo failed)\"))\n", "test_name": "test_api_endpoint", "rerun": "0"}}, "suite_name": "TestCase/Test_First_TestCase.py"}}}, "date": "January 30, 2025", "start_time": 1738232227.988416, "total_suite": 1, "status": "FAIL", "status_list": {"pass": "0", "fail": "1", "skip": "0", "error": "0", "xpass": "0", "xfail": "0", "rerun": "0"}, "total_tests": "1"}